<?xml version="1.0"?>
<robot name="simple_humanoid">

  <link name="torso">
    <visual>
      <geometry>
        <box size="0.1 0.2 0.4"/>
      </geometry>
    </visual>
    <collision>
      <geometry>
        <box size="0.1 0.2 0.4"/>
      </geometry>
    </collision>
    <inertial>
      <mass value="1.0"/>
      <inertia ixx="0.01" ixy="0.0" ixz="0.0" iyy="0.01" iyz="0.0" izz="0.01"/>
    </inertial>
  </link>

  <link name="head">
    <visual>
      <geometry>
        <sphere radius="0.1"/>
      </geometry>
    </visual>
    <collision>
      <geometry>
        <sphere radius="0.1"/>
      </geometry>
    </collision>
    <inertial>
      <mass value="0.5"/>
      <inertia ixx="0.001" ixy="0.0" ixz="0.0" iyy="0.001" iyz="0.0" izz="0.001"/>
    </inertial>
  </link>

  <joint name="neck" type="revolute">
    <parent link="torso"/>
    <child link="head"/>
    <origin xyz="0 0 0.25"/>
    <axis xyz="0 0 1"/>
    <limit lower="-1.57" upper="1.57" effort="10" velocity="1"/>
  </joint>

  <link name="left_upper_arm">
    <visual>
      <geometry>
        <cylinder length="0.3" radius="0.05"/>
      </geometry>
    </visual>
    <collision>
      <geometry>
        <cylinder length="0.3" radius="0.05"/>
      </geometry>
    </collision>
    <inertial>
      <mass value="0.2"/>
      <inertia ixx="0.001" ixy="0.0" ixz="0.0" iyy="0.001" iyz="0.0" izz="0.001"/>
    </inertial>
  </link>

  <joint name="left_shoulder" type="revolute">
    <parent link="torso"/>
    <child link="left_upper_arm"/>
    <origin xyz="0 0.15 0.1"/>
    <axis xyz="0 1 0"/>
    <limit lower="-1.57" upper="1.57" effort="10" velocity="1"/>
  </joint>

  <link name="right_upper_arm">
    <visual>
      <geometry>
        <cylinder length="0.3" radius="0.05"/>
      </geometry>
    </visual>
    <collision>
      <geometry>
        <cylinder length="0.3" radius="0.05"/>
      </geometry>
    </collision>
    <inertial>
      <mass value="0.2"/>
      <inertia ixx="0.001" ixy="0.0" ixz="0.0" iyy="0.001" iyz="0.0" izz="0.001"/>
    </inertial>
  </link>

  <joint name="right_shoulder" type="revolute">
    <parent link="torso"/>
    <child link="right_upper_arm"/>
    <origin xyz="0 -0.15 0.1"/>
    <axis xyz="0 1 0"/>
    <limit lower="-1.57" upper="1.57" effort="10" velocity="1"/>
  </joint>

</robot>
